Mon, 25 Jan 2016 19:35:54 inventory.py[line:51] INFO account(123) is not in cache,just sync from zookeeper...
Mon, 25 Jan 2016 19:35:54 connection.py[line:575] INFO Connecting to 10.74.113.102:2181
Mon, 25 Jan 2016 19:35:54 connection.py[line:282] DEBUG Sending request(xid=None): Connect(protocol_version=0, last_zxid_seen=0, time_out=10000, session_id=0, passwd='\x00\x00\x00\x00\x00\x00\x00\x00\x00\x00\x00\x00\x00\x00\x00\x00', read_only=None)
Mon, 25 Jan 2016 19:35:54 client.py[line:444] INFO Zookeeper connection established, state: CONNECTED
Mon, 25 Jan 2016 19:35:54 connection.py[line:282] DEBUG Sending request(xid=1): GetData(path='/dso/Mapping/Ip2User/123', watcher=<function accountwatcher at 0x10773e938>)
Mon, 25 Jan 2016 19:35:54 connection.py[line:352] DEBUG Received error(xid=1) NoNodeError((), {})
Mon, 25 Jan 2016 19:35:54 inventory.py[line:65] ERROR node (123) can not be found from zookeeper.
Mon, 25 Jan 2016 19:35:54 connection.py[line:282] DEBUG Sending request(xid=2): Close()
Mon, 25 Jan 2016 19:35:54 connection.py[line:542] INFO Closing connection to 10.74.113.102:2181
Mon, 25 Jan 2016 19:35:54 client.py[line:448] INFO Zookeeper session lost, state: CLOSED
